Workbook
Name ajdic: '[2]Budget 2026'!#REF!
Name ajdic: '[2]Budget 2026'!#REF!
Name ajdic: 'REAL-BDGT2026'!#REF!
Name dic: '[2]Budget 2026'!#REF!
Name dic: '[2]Budget 2026'!#REF!
Name dic: 'REAL-BDGT2026'!#REF!
Name dolarbnaabr: '[2]Budget 2026'!#REF!
Name dolarbnaabr: '[2]Budget 2026'!#REF!
Name dolarbnaabr: 'REAL-BDGT2026'!#REF!
Name dolarbnaago: '[2]Budget 2026'!#REF!
Name dolarbnaago: '[2]Budget 2026'!#REF!
Name dolarbnaago: 'REAL-BDGT2026'!#REF!
Name dolarbnadic: '[2]Budget 2026'!#REF!
Name dolarbnadic: '[2]Budget 2026'!#REF!
Name dolarbnadic: 'REAL-BDGT2026'!#REF!
Name dolarbnaene: '[2]Budget 2026'!$I$219
Name dolarbnaene: '[2]Budget 2026'!$I$219
Name dolarbnafeb: '[2]Budget 2026'!#REF!
Name dolarbnafeb: '[2]Budget 2026'!#REF!
Name dolarbnafeb: 'REAL-BDGT2026'!#REF!
Name dolarbnajul: '[2]Budget 2026'!#REF!
Name dolarbnajul: '[2]Budget 2026'!#REF!
Name dolarbnajul: 'REAL-BDGT2026'!#REF!
Name dolarbnajun: '[2]Budget 2026'!#REF!
Name dolarbnajun: '[2]Budget 2026'!#REF!
Name dolarbnajun: 'REAL-BDGT2026'!#REF!
Name dolarbnamar: '[2]Budget 2026'!#REF!
Name dolarbnamar: '[2]Budget 2026'!#REF!
Name dolarbnamar: 'REAL-BDGT2026'!#REF!
Name dolarbnamay: '[2]Budget 2026'!#REF!
Name dolarbnamay: '[2]Budget 2026'!#REF!
Name dolarbnamay: 'REAL-BDGT2026'!#REF!
Name dolarbnanov: '[2]Budget 2026'!#REF!
Name dolarbnanov: '[2]Budget 2026'!#REF!
Name dolarbnanov: 'REAL-BDGT2026'!#REF!
Name dolarbnaoct: '[2]Budget 2026'!#REF!
Name dolarbnaoct: '[2]Budget 2026'!#REF!
Name dolarbnaoct: 'REAL-BDGT2026'!#REF!
Name dolarbnasep: '[2]Budget 2026'!#REF!
Name dolarbnasep: '[2]Budget 2026'!#REF!
Name dolarbnasep: 'REAL-BDGT2026'!#REF!
Name dolarmepabr: '[2]Budget 2026'!#REF!
Name dolarmepabr: '[2]Budget 2026'!#REF!
Name dolarmepabr: 'REAL-BDGT2026'!#REF!
Name dolarmepago: '[2]Budget 2026'!#REF!
Name dolarmepago: '[2]Budget 2026'!#REF!
Name dolarmepago: 'REAL-BDGT2026'!#REF!
Name dolarmepdic: '[2]Budget 2026'!#REF!
Name dolarmepdic: '[2]Budget 2026'!#REF!
Name dolarmepdic: 'REAL-BDGT2026'!#REF!
Name dolarmepfeb: '[2]Budget 2026'!#REF!
Name dolarmepfeb: '[2]Budget 2026'!#REF!
Name dolarmepfeb: 'REAL-BDGT2026'!#REF!
Name dolarmepjul: '[2]Budget 2026'!#REF!
Name dolarmepjul: '[2]Budget 2026'!#REF!
Name dolarmepjul: 'REAL-BDGT2026'!#REF!
Name dolarmepjun: '[2]Budget 2026'!#REF!
Name dolarmepjun: '[2]Budget 2026'!#REF!
Name dolarmepjun: 'REAL-BDGT2026'!#REF!
Name dolarmepmar: '[2]Budget 2026'!#REF!

Sheet REAL-BDGT2026
V1: =(+V40-V14-V15)-((+V40-V14-V15)*5%) -> 2335761067
I2: REAL | J2: REAL | K2: REAL | L2: REAL | M2: REAL | N2: REAL | O2: REAL | P2: REAL | Q2: REAL | R2: REAL | S2: REAL | T2: REAL | V2: REAL | X2: BDGT 2026 | Y2: BDGT 2026 | Z2: BDGT 2026 | AA2: BDGT 2026 | AB2: BDGT 2026 | AC2: BDGT 2026 | AD2: BDGT 2026 | AE2: BDGT 2026 | AF2: BDGT 2026 | AG2: BDGT 2026 | AH2: BDGT 2026 | AI2: BDGT 2026 | AK2: BDGT 2026 | AM2: GAP
V3: Acum Abr | AK3: =+V3 -> Acum Abr | AM3: =+AK3 -> Acum Abr
I4: Ene-26 | J4: 46078 | K4: 46106 | L4: Abr-26 | M4: 46167 | N4: 46198 | O4: 46228 | P4: 46259 | Q4: 46290 | R4: 46320 | S4: 46351 | T4: 46381 | V4: FY 2026 | X4: =+I4 -> Ene-26 | Y4: =+J4 -> 46078 | Z4: =+K4 -> 46106 | AA4: =+L4 -> Abr-26 | AB4: =+M4 -> 46167 | AC4: =+N4 -> 46198 | AD4: =+O4 -> 46228 | AE4: =+P4 -> 46259 | ... AI4: =+T4 -> 46381 | AK4: FY 2026 | AM4: FY 2026
B5: Ingresos por Venta de Servicios
C6: Clientes | L6: 0.05 | M6: 0.05 | N6: 0.05 | O6: 0.05 | P6: 0.05 | Q6: 0.05 | R6: 0.05 | S6: 0.05 | T6: 0.05
D7: Farmacias | I7: =SUM(I8:I19) -> 1891706468 | J7: =SUM(J8:J19) -> 1791176322 | K7: =SUM(K8:K19) -> 2036545616 | L7: =SUM(L8:L19) -> 2086424382 | M7: =SUM(M8:M19) -> 0 | N7: =SUM(N8:N19) -> 0 | O7: =SUM(O8:O19) -> 0 | P7: =SUM(P8:P19) -> 0 | ... T7: =SUM(T8:T19) -> 0 | V7: =SUM(I7:L7) -> 7805852787 | X7: 1.8131602e+09 | Y7: 1.6904679e+09 | Z7: 1.8510241e+09 | AA7: 1.9443481e+09 | AB7: 2.0626141e+09 | AC7: 2.0723756e+09 | AD7: 2.2962548e+09 | AE7: 2.2645018e+09 | AF7: 2.3857082e+09 | AG7: 2.4962105e+09 | AH7: 2.4331575e+09 | AI7: 2.5095454e+09 | AK7: =SUM(X7:AA7) -> 7299000309 | AM7: =+V7-AK7 -> 5.0685248e+08 | AN7: =+AM7/AK7 -> 0.069441356
A8: 2 | C8: Farmalink On Line Prepagas | E8: 5111 | I8: 2.5482214e+08 | J8: 2.2033022e+08 | K8: 2.8260867e+08 | L8: 2.886987e+08 | V8: =SUM(I8:L8) -> 1046459727 | X8: 2.2671581e+08 | Y8: 2.0933465e+08 | Z8: 2.3834042e+08 | AA8: 2.5489008e+08 | AB8: 2.7163249e+08 | AC8: 2.7305075e+08 | AD8: 2.9126764e+08 | AE8: 2.8758108e+08 | AF8: 2.9728318e+08 | AG8: 3.0439589e+08 | AH8: 2.8288845e+08 | AI8: 2.8713178e+08 | AK8: =SUM(X8:AA8) -> 9.2928096e+08
A9: 2 | C9: Farmalink On Line Apross | E9: 5111 | I9: 34319465 | J9: 33720492 | K9: 33758789 | L9: 42091264 | V9: =SUM(I9:L9) -> 1.4389001e+08 | X9: 32504828 | Y9: 29340012 | Z9: 32659622 | AA9: 33997073 | AB9: 36403562 | AC9: 37854255 | AD9: 40093476 | AE9: 39347218 | AF9: 39932286 | AG9: 43485128 | AH9: 37731478 | AI9: 38297450 | AK9: =SUM(X9:AA9) -> 1.2850153e+08
A10: 2 | C10: Farmalink On Line IOMA | E10: 5111 | I10: 1.2932564e+08 | J10: 1.420488e+08 | K10: 1.5145417e+08 | L10: 1.5695356e+08 | V10: =SUM(I10:L10) -> 579782177 | X10: 1.2537173e+08 | Y10: 1.2020175e+08 | Z10: 1.3213189e+08 | AA10: 1.405428e+08 | AB10: 1.4845625e+08 | AC10: 1.4989528e+08 | AD10: 1.6421312e+08 | AE10: 1.5896456e+08 | AF10: 1.6439587e+08 | AG10: 1.7079632e+08 | AH10: 1.5598071e+08 | AI10: 1.5832042e+08 | AK10: =SUM(X10:AA10) -> 5.1824817e+08
A11: 2 | C11: Farmalink Receta Electronica Prepagas | E11: 5111 | I11: 11823897 | J11: 14400808 | K11: 15955905 | L11: 16626577 | V11: =SUM(I11:L11) -> 58807186 | X11: 9929897.1 | Y11: 9851405.1 | Z11: 11534954 | AA11: 12421706 | AB11: 13411096 | AC11: 13607751 | AD11: 14981324 | AE11: 15231149 | AF11: 15868240 | AG11: 16106264 | AH11: 13786168 | AI11: 13992960 | AK11: =SUM(X11:AA11) -> 43737963
A12: 2 | C12: Farmalink Receta Electronica Apross | E12: 5111 | I12: 2973743.1 | J12: 2532284.2 | K12: 2619109.9 | L12: 3360763.1 | V12: =SUM(I12:L12) -> 11485900 | X12: 2601231.5 | Y12: 2347932.3 | Z12: 2614041.1 | AA12: 2720038.7 | AB12: 2914236.5 | AC12: 3029667.5 | AD12: 3209236.7 | AE12: 3149912.2 | AF12: 3195899.1 | AG12: 3243837.6 | AH12: 3018821.2 | AI12: 3064103.5 | AK12: =SUM(X12:AA12) -> 10283244
A13: 2 | C13: Farmalink Receta Electronica IOMA | E13: 5111 | I13: 3753069.9 | J13: 4916448 | K13: 5834881.9 | L13: 4463788.4 | V13: =SUM(I13:L13) -> 18968188 | X13: 2894915.9 | Y13: 3065993.8 | Z13: 3447951 | AA13: 3581827.8 | AB13: 3984423.7 | AC13: 4087578.9 | AD13: 4662027.9 | AE13: 4743490.6 | AF13: 4965834.5 | AG13: 5040322 | AH13: 3975273.3 | AI13: 4034902.4 | AK13: =SUM(X13:AA13) -> 12990688
A14: 2 | C14: Farmalink On Line PAMI | E14: 5111 | I14: 1.4115059e+09 | J14: 1.3293495e+09 | K14: 1.501823e+09 | L14: 1.5255242e+09 | V14: =SUM(I14:L14) -> 5768202635 | X14: 1.3719931e+09 | Y14: 1.2767444e+09 | Z14: 1.3877895e+09 | AA14: 1.4172071e+09 | AB14: 1.4678905e+09 | AC14: 1.4405788e+09 | AD14: 1.574275e+09 | AE14: 1.5207368e+09 | AF14: 1.5766526e+09 | AG14: 1.6216858e+09 | AH14: 1.5728801e+09 | AI14: 1.5964733e+09 | AK14: =SUM(X14:AA14) -> 5453734002
A15: 2 | C15: Farmalink On Line PAMI Imposiciones | E15: 5111 | I15: 41967144 | J15: 42804261 | K15: 41062515 | L15: 47361867 | V15: =SUM(I15:L15) -> 1.7319579e+08 | X15: 39904737 | Y15: 38337796 | Z15: 41261745 | AA15: 42256534 | AB15: 43226277 | AC15: 40927370 | AD15: 44765327 | AE15: 43295302 | AF15: 45556153 | AG15: 46239495 | AH15: 46898200 | AI15: 47601673 | AK15: =SUM(X15:AA15) -> 1.6176081e+08
A16: 2 | C16: Farmalink Presentaciones Digitales | E16: 5111 | I16: 0 | J16: 0 | K16: 0 | L16: 0 | V16: =SUM(I16:L16) -> 0 | X16: 0 | Y16: 0 | Z16: 0 | AA16: 35430177 | AB16: 73394523 | AC16: 1.0804341e+08 | AD16: 1.574275e+08 | AE16: 1.900921e+08 | AF16: 2.3649789e+08 | AG16: 2.8379502e+08 | AH16: 3.1457601e+08 | AI16: 3.5920648e+08 | AK16: =SUM(X16:AA16) -> 35430177
A17: 1 | C17: Provincia A.R.T. S.A. | E17: 5111 | I17: 1215432.5 | J17: 1073509.3 | K17: 1428548.4 | L17: 1343686 | V17: =SUM(I17:L17) -> 5061176.2 | X17: 1243983.8 | Y17: 1243983.8 | Z17: 1243983.8 | AA17: 1300806.9 | AB17: 1300806.9 | AC17: 1300806.9 | AD17: 1360225.7 | AE17: 1360225.7 | AF17: 1360225.7 | AG17: 1422358.6 | AH17: 1422358.6 | AI17: 1422358.6 | AK17: =SUM(X17:AA17) -> 5032758.2
V18: =SUM(I18:L18) -> 0 | AK18: =SUM(X18:AA18) -> 0
V19: =SUM(I19:L19) -> 0 | AK19: =SUM(X19:AA19) -> 0
D20: Laboratorios | I20: =SUM(I21:I36) -> 1.3048782e+08 | J20: =SUM(J21:J36) -> 1.5448823e+08 | K20: =SUM(K21:K36) -> 1.2145758e+08 | L20: =SUM(L21:L36) -> 1.396693e+08 | M20: =SUM(M21:M36) -> 0 | N20: =SUM(N21:N36) -> 0 | O20: =SUM(O21:O36) -> 0 | P20: =SUM(P21:P36) -> 0 | ... T20: =SUM(T21:T36) -> 0 | V20: =SUM(I20:L20) -> 5.4610293e+08 | X20: 1.3261321e+08 | Y20: 1.2981524e+08 | Z20: 1.2688779e+08 | AA20: 1.3626315e+08 | AB20: 1.3731988e+08 | AC20: 1.3841524e+08 | AD20: 1.4752257e+08 | AE20: 1.4905394e+08 | AF20: 1.5072312e+08 | AG20: 1.6143844e+08 | AH20: 1.6626184e+08 | AI20: 1.738785e+08 | AK20: =SUM(X20:AA20) -> 5.2557939e+08 | AM20: =+V20-AK20 -> 20523541 | AN20: =+AM20/AK20 -> 0.039049364
A21: 1 | C21: Astrazeneca S.A. | E21: 5111 | I21: 22166717 | J21: 20929744 | K21: 19689476 | L21: 22612629 | V21: =SUM(I21:L21) -> 85398567 | X21: 21263922 | Y21: 21543070 | Z21: 21826007 | AA21: 22112786 | AB21: 22403461 | AC21: 22698085 | AD21: 22996715 | AE21: 23299406 | AF21: 23606214 | AG21: 23917198 | AH21: 24232415 | AI21: 24551925 | AK21: =SUM(X21:AA21) -> 86745786
A22: 1 | C22: Avanter S.R.L | D22: viejos labos | E22: 5111 | I22: 62130128 | J22: 48199032 | K22: 39454206 | L22: 45028730 | V22: =SUM(I22:L22) -> 1.948121e+08 | X22: 43139377 | Y22: 39544429 | Z22: 35949481 | AA22: 43230334 | AB22: 43230334 | AC22: 43230334 | AD22: 50177579 | AE22: 50177579 | AF22: 50177579 | AG22: 58398675 | AH22: 61179564 | AI22: 66741342 | AK22: =SUM(X22:AA22) -> 1.6186362e+08
A23: 1 | C23: Avanter S.R.L | D23: nuevos labos | E23: 5111 | I23: 0 | J23: 0 | K23: 0 | L23: 0 | V23: =SUM(I23:L23) -> 0 | X23: 270600 | Y23: 369600 | Z23: 379500 | AA23: 435600 | AB23: 471900 | AC23: 471900 | AD23: 495000 | AE23: 495000 | AF23: 495000 | AG23: 518100 | AH23: 518100 | AI23: 518100 | AK23: =SUM(X23:AA23) -> 1455300
A24: 1 | C24: Bayer Argentina S.A. | E24: 5111 | I24: 987716.02 | J24: 972221.92 | K24: 954267.72 | L24: 1044493.2 | V24: =SUM(I24:L24) -> 3958698.8 | X24: 893794.9 | Y24: 907201.83 | Z24: 920809.85 | AA24: 934622 | AB24: 948641.33 | AC24: 962870.95 | AD24: 977314.02 | AE24: 991973.73 | AF24: 1006853.3 | AG24: 1021956.1 | AH24: 1037285.5 | AI24: 1052844.8 | AK24: =SUM(X24:AA24) -> 3656428.6
A25: 1 | C25: Ceoderma S.A. | E25: 5111 | I25: 567084.6 | J25: -407194.8 | K25: 0 | L25: 0 | V25: =SUM(I25:L25) -> 159889.8 | X25: 564624.94 | Y25: 564624.94 | Z25: 564624.94 | AA25: 590416.09 | AB25: 590416.09 | AC25: 590416.09 | AD25: 617385.33 | AE25: 617385.33 | AF25: 617385.33 | AG25: 645586.49 | AH25: 645586.49 | AI25: 645586.49 | AK25: =SUM(X25:AA25) -> 2284290.9
A26: 1 | C26: Iqvia Solutions Argentina | E26: 5111 | I26: 0 | J26: 40336839 | K26: =+J26/2 -> 20168419 | L26: 20168419 | V26: =SUM(I26:L26) -> 80673677 | X26: 21256746 | Y26: 21256746 | Z26: 21256746 | AA26: 21256746 | AB26: 21256746 | AC26: 21256746 | AD26: 21256746 | AE26: 21256746 | AF26: 21256746 | AG26: 21256746 | AH26: 21256746 | AI26: 21256746 | AK26: =SUM(X26:AA26) -> 85026984
A27: 1 | C27: Max Vision | E27: 5111 | I27: 1170304.5 | J27: 1313290.7 | K27: 1488814.9 | L27: 1368036.9 | V27: =SUM(I27:L27) -> 5340447 | X27: 1213256.2 | Y27: 1213256.2 | Z27: 1213256.2 | AA27: 1268675.8 | AB27: 1268675.8 | AC27: 1268675.8 | AD27: 1326626.8 | AE27: 1326626.8 | AF27: 1326626.8 | AG27: 1387225 | AH27: 1387225 | AI27: 1387225 | AK27: =SUM(X27:AA27) -> 4908444.3
A28: 1 | C28: Panalab Argentina S.A. | D28: Manual | E28: 5111 | I28: 11044183 | J28: 8443666.5 | K28: 9320434.8 | L28: 9289060.3 | V28: =SUM(I28:L28) -> 38097345 | X28: 10944530 | Y28: 9997828 | Z28: 9133015.9 | AA28: 8343010 | AB28: 7621339.7 | AC28: 6962093.8 | AD28: 6359872.7 | AE28: 5809743.7 | AF28: 5307200.9 | AG28: 4848128 | AH28: 4428764.9 | AI28: 4045676.7 | AK28: =SUM(X28:AA28) -> 38418384
A29: 1 | C29: Panalab Argentina S.A. | D29: Digital | E29: 5111 | I29: 26012630 | J29: 27248448 | K29: 30514692 | L29: 31709520 | V29: =SUM(I29:L29) -> 1.1548529e+08 | X29: 24928651 | Y29: 26024300 | Z29: 27183791 | AA29: 28463775 | AB29: 29763372 | AC29: 31139780 | AD29: 32652897 | AE29: 34197940 | AF29: 35835467 | AG29: 37628912 | AH29: 39469556 | AI29: 41421630 | AK29: =SUM(X29:AA29) -> 1.0660052e+08
A30: 1 | C30: Sidus Dermocosmética S.A | E30: 5111 | I30: 2732192.8 | J30: 2975325 | K30: -4664299.4 | L30: 2929705.4 | V30: =SUM(I30:L30) -> 3972923.7 | X30: 4272538.2 | Y30: 4317548.3 | Z30: 4363233.6 | AA30: 4467700.8 | AB30: 4514766.9 | AC30: 4562539 | AD30: 4671778.1 | AE30: 4720994.1 | AF30: 4770948.4 | AG30: 4885177.3 | AH30: 4936641.5 | AI30: 4988877.6 | AK30: =SUM(X30:AA30) -> 17421021
A31: 1 | C31: Sidus S.A. | E31: 5111 | I31: 1233443.7 | J31: 766721.67 | K31: 131940.99 | L31: 1766721.7 | V31: =SUM(I31:L31) -> 3898828 | X31: 1341762.9 | Y31: 1533443.3 | Z31: 1533443.3 | AA31: 1533443.3 | AB31: 1603488.5 | AC31: 1603488.5 | AD31: 1603488.5 | AE31: 1676733.3 | AF31: 1676733.3 | AG31: 1676733.3 | AH31: 1753323.7 | AI31: 1753323.7 | AK31: =SUM(X31:AA31) -> 5942092.9
A32: 1 | C32: Unyc S.A. | E32: 5111 | I32: 7990.89 | J32: 8033.18 | K32: 7296.03 | L32: 8321.72 | V32: =SUM(I32:L32) -> 31641.82 | X32: 11709.34 | Y32: 11709.34 | Z32: 12304.52 | AA32: 12304.52 | AB32: 12304.52 | AC32: 12866.571 | AD32: 12866.571 | AE32: 12866.571 | AF32: 13454.295 | AG32: 13454.295 | AH32: 13454.295 | AI32: 14068.865 | AK32: =SUM(X32:AA32) -> 48027.722 | AO32: =+L40*0.21 -> 4.7000695e+08
A33: 1 | C33: HEALTHCARE MARKETING GROUP S | E33: 5111 | I33: 396875.5 | J33: 971875.5 | K33: 1351875.5 | L33: 904782.22 | V33: =SUM(I33:L33) -> 3625408.7 | X33: 367193.57 | Y33: 367193.57 | Z33: 367193.57 | AA33: 383966.38 | AB33: 383966.38 | AC33: 383966.38 | AD33: 401505.34 | AE33: 401505.34 | AF33: 401505.34 | AG33: 419845.45 | AH33: 419845.45 | AI33: 419845.45 | AK33: =SUM(X33:AA33) -> 1485547.1
A34: 1 | C34: Colgate palmolive | E34: 5111 | I34: 2038550.1 | J34: 1730226.4 | K34: 2540459.7 | L34: 2338884.9 | V34: =SUM(I34:L34) -> 8648121.1 | X34: 1319500 | Y34: 1339292.5 | Z34: 1359381.9 | AA34: 1379772.6 | AB34: 1400469.2 | AC34: 1421476.2 | AD34: 1442798.4 | AE34: 1464440.4 | AF34: 1486407 | AG34: 1508703.1 | AH34: 1531333.6 | AI34: 1554303.6 | AK34: =SUM(X34:AA34) -> 5397947
A35: 1 | C35: Nuevos labos - LAZAR | E35: 5111 | I35: =500000*0 -> 0 | J35: 1000000 | K35: 500000 | L35: 500000 | V35: =SUM(I35:L35) -> 2000000 | X35: 825000 | Y35: 825000 | Z35: 825000 | AA35: 1850000 | AB35: 1850000 | AC35: 1850000 | AD35: 2530000 | AE35: 2605000 | AF35: 2745000 | AG35: 3312000 | AH35: 3452000 | AI35: 3527000 | AK35: =SUM(X35:AA35) -> 4325000
A36: 1 | E36: 5111 | AK36: =SUM(X36:AA36) -> 0
D37: Medicina | I37: =SUM(I38:I39) -> 11164532 | J37: =SUM(J38:J39) -> 36974029 | K37: =SUM(K38:K39) -> -12034640 | L37: =SUM(L38:L39) -> 12034640 | M37: =SUM(M38:M39) -> 0 | N37: =SUM(N38:N39) -> 0 | O37: =SUM(O38:O39) -> 0 | P37: =SUM(P38:P39) -> 0 | ... T37: =SUM(T38:T39) -> 0 | V37: =SUM(I37:L37) -> 48138562 | X37: 11882737 | Y37: 11882737 | Z37: 11882737 | AA37: 12425521 | AB37: 12425521 | AC37: 12425521 | AD37: 12993099 | AE37: 12993099 | AF37: 12993099 | AG37: 13586602 | AH37: 13586602 | AI37: 13586602 | AK37: =SUM(X37:AA37) -> 48073732 | AM37: =+V37-AK37 -> 64829.538 | AN37: =+AM37/AK37 -> 0.0013485439
A38: 1 | C38: Obra Social de la Act. de Seguro | E38: 5111 | I38: 11164532 | J38: =12904748.89+(12034640*2) -> 36974029 | K38: -12034640 | L38: 12034640 | V38: =SUM(I38:K38) -> 36103921 | X38: 11882737 | Y38: 11882737 | Z38: 11882737 | AA38: 12425521 | AB38: 12425521 | AC38: 12425521 | AD38: 12993099 | AE38: 12993099 | AF38: 12993099 | AG38: 13586602 | AH38: 13586602 | AI38: 13586602 | AK38: =SUM(X38:Z38) -> 35648211
C40: Subtotal Ingresos | I40: =+I37+I20+I7 -> 2033358817 | J40: =+J37+J20+J7 -> 1982638579 | K40: =+K37+K20+K7 -> 2145968560 | L40: =+L37+L20+L7 -> 2238128327 | M40: =+M37+M20+M7 -> 0 | N40: =+N37+N20+N7 -> 0 | O40: =+O37+O20+O7 -> 0 | P40: =+P37+P20+P7 -> 0 | ... T40: =+T37+T20+T7 -> 0 | V40: =SUM(I40:L40) -> 8400094283 | X40: 1.9576561e+09 | Y40: 1.8321659e+09 | Z40: 1.9897946e+09 | AA40: 2.0930368e+09 | AB40: 2.2123595e+09 | AC40: 2.2232164e+09 | AD40: 2.4567705e+09 | AE40: 2.4265489e+09 | AF40: 2.5494244e+09 | AG40: 2.6712355e+09 | AH40: 2.613006e+09 | AI40: 2.6970105e+09 | AK40: =SUM(X40:AA40) -> 7872653434 | AM40: =+V40-AK40 -> 5.2744085e+08 | AN40: =+AM40/AK40 -> 0.066996579 | AO40: =+L40-AA40 -> 1.4509154e+08
C41: IIBB | E41: 5612 | I41: -1.2061955e+08 | J41: -124410617 | K41: -1.2598475e+08 | L41: -1.1082338e+08 | M41: =-M40*M6 -> 0 | N41: =-N40*N6 -> 0 | O41: =-O40*O6 -> 0 | P41: =-P40*P6 -> 0 | Q41: =-Q40*Q6 -> 0 | R41: =-R40*R6 -> 0 | S41: =-S40*S6 -> 0 | T41: =-T40*T6 -> 0 | V41: =SUM(I41:L41) -> -481838296 | X41: -97882807 | Y41: -91608295 | Z41: -99489730 | AA41: -1.0465184e+08 | AB41: -1.1061798e+08 | AC41: -1.1116082e+08 | AD41: -1.2283853e+08 | AE41: -1.2132744e+08 | AF41: -1.2747122e+08 | AG41: -1.3356178e+08 | AH41: -1.306503e+08 | AI41: -1.3485052e+08 | AK41: =SUM(X41:AA41) -> -3.9363267e+08
...

Sheet Trazabilidad
A1: TRAZABILIDAD — GOLD ECONÓMICO 2026 (Ene-Abr)
A2: Ingresá la fila y el mes para filtrar los movimientos del Mayor
A3: Fila Gold → | D3: Mes → | E3: Abr
A4: Concepto: | B4: {=IFERROR(INDEX('REAL-BDGT2026'!C:C,B3),"")} | D4: Valor Gold: | E4: {=IFERROR(IF(E3="Ene",INDEX('REAL-BDGT2026'!I:I,B3),IF(E3="Feb",INDEX('REAL-BDGT2026'!J:J,B3),IF(E3="Mar",INDEX('REAL-BDGT2026'!K:K,B3),IF(E3="Abr",INDEX('REAL-BDGT2026'!L:L,B3),"")))),"")}
E5: REAL
A6: Mes | C6: Concepto Gold | D6: Cód | F6: Detalle | G6: Débito | H6: Crédito | I6: Neto Mayor | J6: Valor Gold | K6: Diferencia
A7: Ene | B7: 8 | C7: Farmalink On Line Prepagas | D7: 5111 | E7: Farmalink S.A. | F7: Servicio Basico Online PREPAGAS - Noviembre 2025 | G7: 0 | H7: 2.3328759e+08 | I7: -2.3328759e+08
A8: Ene | B8: 8 | C8: Farmalink On Line Prepagas | D8: 5111 | F8: Disolución Previsión dic25 FLK Prepagas On Line | G8: 256042440 | H8: 0 | I8: 256042440
A9: Ene | B9: 8 | C9: Farmalink On Line Prepagas | D9: 5111 | F9: Disolución Previsión nov25 FLK Prepagas On Line | G9: 2.3328759e+08 | H9: 0 | I9: 2.3328759e+08
A10: Ene | B10: 8 | C10: Farmalink On Line Prepagas | D10: 5111 | F10: Constitución Previsión dic25 FLK Prepagas On Line | G10: 0 | H10: 2.5665427e+08 | I10: -2.5665427e+08
A11: Ene | B11: 8 | C11: Farmalink On Line Prepagas | D11: 5111 | F11: Constitución Previsión ene26 FLK Prepagas On Line | G11: 0 | H11: 2.542103e+08 | I11: -2.542103e+08
A12: Ene | B12: 8 | C12: Farmalink On Line Prepagas | D12: TOTAL | F12: Neto Mayor vs Valor Gold | G12: 4.8933003e+08 | H12: 7.4415217e+08 | I12: -2.5482214e+08 | J12: 2.5482214e+08 | K12: 0
A13: Ene | B13: 9 | C13: Farmalink On Line Apross | D13: 5111 | E13: Farmalink S.A. | F13: Servicio Basico Online APROSS - Noviembre 2025 | G13: 0 | H13: 30637826 | I13: -30637826
A14: Ene | B14: 9 | C14: Farmalink On Line Apross | D14: 5111 | F14: Disolución Previsión nov25 FLK Apross On Line | G14: 30637826 | H14: 0 | I14: 30637826
A15: Ene | B15: 9 | C15: Farmalink On Line Apross | D15: 5111 | F15: Disolución Previsión dic25 FLK Apross On Line | G15: 30875706 | H15: 0 | I15: 30875706
A16: Ene | B16: 9 | C16: Farmalink On Line Apross | D16: 5111 | F16: Constitución Previsión dic25 FLK Apross On Line | G16: 0 | H16: 34381801 | I16: -34381801
A17: Ene | B17: 9 | C17: Farmalink On Line Apross | D17: 5111 | F17: Constitución Previsión ene26 FLK Apross On Line | G17: 0 | H17: 30813370 | I17: -30813370
A18: Ene | B18: 9 | C18: Farmalink On Line Apross | D18: TOTAL | F18: Neto Mayor vs Valor Gold | G18: 61513532 | H18: 95832997 | I18: -34319465 | J18: 34319465 | K18: 0
A19: Ene | B19: 10 | C19: Farmalink On Line IOMA | D19: 5111 | E19: Farmalink S.A. | F19: Servicio Basico Online IOMA - Noviembre 2025 | G19: 0 | H19: 1.2962802e+08 | I19: -1.2962802e+08
A20: Ene | B20: 10 | C20: Farmalink On Line IOMA | D20: 5111 | F20: Disolución Previsión nov25 FLK IOMA On Line | G20: 1.2962802e+08 | H20: 0 | I20: 1.2962802e+08
A21: Ene | B21: 10 | C21: Farmalink On Line IOMA | D21: 5111 | F21: Disolución Previsión dic25 FLK IOMA On Line | G21: 140576859 | H21: 0 | I21: 140576859
A22: Ene | B22: 10 | C22: Farmalink On Line IOMA | D22: 5111 | F22: Constitución Previsión dic25 FLK IOMA On Line | G22: 0 | H22: 1.4355489e+08 | I22: -1.4355489e+08
A23: Ene | B23: 10 | C23: Farmalink On Line IOMA | D23: 5111 | F23: Constitución Previsión ene26 FLK IOMA On Line | G23: 0 | H23: 126347606 | I23: -126347606
A24: Ene | B24: 10 | C24: Farmalink On Line IOMA | D24: TOTAL | F24: Neto Mayor vs Valor Gold | G24: 2.7020488e+08 | H24: 3.9953052e+08 | I24: -1.2932564e+08 | J24: 1.2932564e+08 | K24: 0
A25: Ene | B25: 11 | C25: Farmalink Receta Electronica Prepagas | D25: 5111 | E25: Farmalink S.A. | F25: Servicio Basico Online - RECETA ELECTRONICA - PREPAGAS - Noviembre 2025 | G25: 0 | H25: 12858929 | I25: -12858929
A26: Ene | B26: 11 | C26: Farmalink Receta Electronica Prepagas | D26: 5111 | F26: Disolución Previsión dic25 FLK Prepagas Receta Electronica On Line | G26: 12648510 | H26: 0 | I26: 12648510
A27: Ene | B27: 11 | C27: Farmalink Receta Electronica Prepagas | D27: 5111 | F27: Disolución Previsión nov25 FLK Prepagas Receta Electronica On Line | G27: 12858929 | H27: 0 | I27: 12858929
A28: Ene | B28: 11 | C28: Farmalink Receta Electronica Prepagas | D28: 5111 | F28: Constitución Previsión dic25 FLK Prepagas Receta Electronica On Line | G28: 0 | H28: 14422466 | I28: -14422466
A29: Ene | B29: 11 | C29: Farmalink Receta Electronica Prepagas | D29: 5111 | F29: Constitución Previsión ene26 FLK Prepagas Receta Electronica On Line | G29: 0 | H29: 10049942 | I29: -10049942
A30: Ene | B30: 11 | C30: Farmalink Receta Electronica Prepagas | D30: TOTAL | F30: Neto Mayor vs Valor Gold | G30: 25507439 | H30: 37331336 | I30: -11823897 | J30: 11823897 | K30: -0.0063000005
A31: Ene | B31: 12 | C31: Farmalink Receta Electronica Apross | D31: 5111 | E31: Farmalink S.A. | F31: Servicio Basico Online - RECETA ELECTRONICA - APROSS - Noviembre 2025 | G31: 0 | H31: 2450645.9 | I31: -2450645.9
A32: Ene | B32: 12 | C32: Farmalink Receta Electronica Apross | D32: 5111 | F32: Disolución Previsión nov25 FLK Apross Receta Electronica On Line | G32: 2450645.9 | H32: 0 | I32: 2450645.9
A33: Ene | B33: 12 | C33: Farmalink Receta Electronica Apross | D33: 5111 | F33: Disolución Previsión dic25 FLK Apross Receta Electronica On Line | G33: 2409240 | H33: 0 | I33: 2409240
A34: Ene | B34: 12 | C34: Farmalink Receta Electronica Apross | D34: 5111 | F34: Constitución Previsión dic25 FLK Apross Receta Electronica On Line | G34: 0 | H34: 2750304.9 | I34: -2750304.9
A35: Ene | B35: 12 | C35: Farmalink Receta Electronica Apross | D35: 5111 | F35: Constitución Previsión ene26 FLK Apross Receta Electronica On Line | G35: 0 | H35: 2632678.3 | I35: -2632678.3
A36: Ene | B36: 12 | C36: Farmalink Receta Electronica Apross | D36: TOTAL | F36: Neto Mayor vs Valor Gold | G36: 4859885.9 | H36: 7833629 | I36: -2973743.1 | J36: 2973743.1 | K36: -0.0055
A37: Ene | B37: 13 | C37: Farmalink Receta Electronica IOMA | D37: 5111 | E37: Farmalink S.A. | F37: Servicio Basico Online - RECETA ELECTRONICA - IOMA - Noviembre 2025 | G37: 0 | H37: 4122534 | I37: -4122534
A38: Ene | B38: 13 | C38: Farmalink Receta Electronica IOMA | D38: 5111 | F38: Disolución Previsión nov25 FLK IOMA Receta Electronica On Line | G38: 4122534 | H38: 0 | I38: 4122534
A39: Ene | B39: 13 | C39: Farmalink Receta Electronica IOMA | D39: 5111 | F39: Disolución Previsión dic25 FLK IOMA Receta Electronica On Line | G39: 3901500 | H39: 0 | I39: 3901500
A40: Ene | B40: 13 | C40: Farmalink Receta Electronica IOMA | D40: 5111 | F40: Constitución Previsión dic25 FLK IOMA Receta Electronica On Line | G40: 0 | H40: 4722130.2 | I40: -4722130.2
...

Sheet Premisas
C2: (al 30/09/25) | I2: (al 30/09/25)
A4: Ventas | B4: Budget | C4: RFC | D4: % de | E4: inflación | F4: crecimiento | H4: Ventas | I4: RFC | J4: Budget | K4: % de | L4: inflación
A5: (sin incidencia IIBB) | B5: FY 2026 | C5: FY 2025 | D5: crecimiento | E5: estimada 2026 | F5: neto | H5: (sin incidencia IIBB) | I5: FY 2025 | J5: FY 2025 | K5: crecimiento | L5: proyectada 2025
A6: Farmacias | B6: =+'REAL-BDGT2026'!V7 -> 7805852787 | C6: =+'REAL-BDGT2026'!#REF! -> #ERROR! | D6: =+B6/C6-1 -> #ERROR! | E6: 0.1956 | F6: =(+D6-$E$6) -> #ERROR! | H6: Farmacias | I6: =+C6 -> #ERROR! | J6: =+'REAL-BDGT2026'!#REF! -> #ERROR! | K6: =+I6/J6-1 -> #ERROR! | L6: 0.2982
A7: Laboratorios | B7: =+'REAL-BDGT2026'!V20 -> 5.4610293e+08 | C7: =+'REAL-BDGT2026'!#REF! -> #ERROR! | D7: =+B7/C7-1 -> #ERROR! | F7: =(+D7-$E$6) -> #ERROR! | H7: Laboratorios | I7: =+C7 -> #ERROR! | J7: =+'REAL-BDGT2026'!#REF! -> #ERROR! | K7: =+I7/J7-1 -> #ERROR!
A8: Medicina | B8: =+'REAL-BDGT2026'!V37 -> 48138562 | C8: =+'REAL-BDGT2026'!#REF! -> #ERROR! | D8: =+B8/C8-1 -> #ERROR! | F8: =(+D8-$E$6) -> #ERROR! | H8: Medicina | I8: =+C8 -> #ERROR! | J8: =+'REAL-BDGT2026'!#REF! -> #ERROR! | K8: =+I8/J8-1 -> #ERROR!
A9: Total Ventas | B9: =SUM(B6:B8) -> 8400094283 | C9: =SUM(C6:C8) -> #ERROR! | D9: =+B9/C9-1 -> #ERROR! | F9: =(+D9-$E$6) -> #ERROR! | H9: Total Ventas | I9: =SUM(I6:I8) -> #ERROR! | J9: =SUM(J6:J8) -> #ERROR! | K9: =+I9/J9-1 -> #ERROR!
A10: Costos | H10: Costos
A11: Desarrollo | B11: =+'REAL-BDGT2026'!V46 -> 1.4876823e+08 | C11: =+'REAL-BDGT2026'!#REF! -> #ERROR! | D11: =+B11/C11-1 -> #ERROR! | F11: =(+D11-$E$6) -> #ERROR! | H11: Desarrollo | I11: =+C11 -> #ERROR! | J11: =+'REAL-BDGT2026'!#REF! -> #ERROR! | K11: =+I11/J11-1 -> #ERROR!
A12: Servicios Plataforma | B12: =+'REAL-BDGT2026'!V58 -> 12554861 | C12: =+'REAL-BDGT2026'!#REF! -> #ERROR! | D12: =+B12/C12-1 -> #ERROR! | F12: =(+D12-$E$6) -> #ERROR! | H12: Servicios Plataforma | I12: =+C12 -> #ERROR! | J12: =+'REAL-BDGT2026'!#REF! -> #ERROR! | K12: =+I12/J12-1 -> #ERROR!
A13: Servidores | B13: =+'REAL-BDGT2026'!V70 -> 21292483 | C13: =+'REAL-BDGT2026'!#REF! -> #ERROR! | D13: =+B13/C13-1 -> #ERROR! | F13: =(+D13-$E$6) -> #ERROR! | H13: Servidores | I13: =+C13 -> #ERROR! | J13: =+'REAL-BDGT2026'!#REF! -> #ERROR! | K13: 1
A14: Servicios Plataforma Clouhesive | B14: =+'REAL-BDGT2026'!V73 -> 0 | C14: =+'REAL-BDGT2026'!#REF! -> #ERROR! | D14: =+B14/C14-1 -> #ERROR! | F14: =(+D14-$E$6) -> #ERROR! | H14: Servicios Plataforma Clouhesive | I14: =+C14 -> #ERROR! | J14: =+'REAL-BDGT2026'!#REF! -> #ERROR! | K14: 1
A15: Soporte Operativo | B15: =+'REAL-BDGT2026'!V75 -> 52937079 | C15: =+'REAL-BDGT2026'!#REF! -> #ERROR! | D15: =+B15/C15-1 -> #ERROR! | F15: =(+D15-$E$6) -> #ERROR! | H15: Soporte Operativo | I15: =+C15 -> #ERROR! | J15: =+'REAL-BDGT2026'!#REF! -> #ERROR! | K15: =+I15/J15-1 -> #ERROR!
A16: Proyectos | B16: =+'REAL-BDGT2026'!V81 -> 1.1170751e+08 | C16: =+'REAL-BDGT2026'!#REF! -> #ERROR! | D16: =+B16/C16-1 -> #ERROR! | F16: =(+D16-$E$6) -> #ERROR! | H16: Proyectos | I16: =+C16 -> #ERROR! | J16: =+'REAL-BDGT2026'!#REF! -> #ERROR! | K16: =+I16/J16-1 -> #ERROR!
A17: BZ | B17: =+'REAL-BDGT2026'!V87 -> 4.7792033e+08 | C17: =+'REAL-BDGT2026'!#REF! -> #ERROR! | D17: =+B17/C17-1 -> #ERROR! | F17: =(+D17-$E$6) -> #ERROR! | H17: BZ | I17: =+C17 -> #ERROR! | J17: =+'REAL-BDGT2026'!#REF! -> #ERROR! | K17: =+I17/J17-1 -> #ERROR!
A18: Admin, Legales y Otros | B18: =+'REAL-BDGT2026'!V93 -> 28560202 | C18: =+'REAL-BDGT2026'!#REF! -> #ERROR! | D18: =+B18/C18-1 -> #ERROR! | F18: =(+D18-$E$6) -> #ERROR! | H18: Admin, Legales y Otros | I18: =+C18 -> #ERROR! | J18: =+'REAL-BDGT2026'!#REF! -> #ERROR! | K18: =+I18/J18-1 -> #ERROR!
A19: Personal | B19: =+'REAL-BDGT2026'!V106 -> 6.0124638e+08 | C19: =+'REAL-BDGT2026'!#REF! -> #ERROR! | D19: =+B19/C19-1 -> #ERROR! | F19: =(+D19-$E$6) -> #ERROR! | H19: Personal | I19: =+C19 -> #ERROR! | J19: =+'REAL-BDGT2026'!#REF! -> #ERROR! | K19: =+I19/J19-1 -> #ERROR!
A20: Oficina | B20: =+'REAL-BDGT2026'!V128 -> 43401843 | C20: =+'REAL-BDGT2026'!#REF! -> #ERROR! | D20: =+B20/C20-1 -> #ERROR! | F20: =(+D20-$E$6) -> #ERROR! | H20: Oficina | I20: =+C20 -> #ERROR! | J20: =+'REAL-BDGT2026'!#REF! -> #ERROR! | K20: =+I20/J20-1 -> #ERROR!
A21: Gastos de Organización | B21: =+'REAL-BDGT2026'!V151 -> 55388959 | C21: =+'REAL-BDGT2026'!#REF! -> #ERROR! | D21: =+B21/C21-1 -> #ERROR! | F21: =(+D21-$E$6) -> #ERROR! | H21: Gastos de Organización | I21: =+C21 -> #ERROR! | J21: =+'REAL-BDGT2026'!#REF! -> #ERROR! | K21: 1
A22: Impuesto al débito y al crédito | B22: =+'REAL-BDGT2026'!V154 -> 0 | C22: =+'REAL-BDGT2026'!#REF! -> #ERROR! | H22: Impuesto al débito y al crédito | I22: =+C22 -> #ERROR! | J22: =+'REAL-BDGT2026'!#REF! -> #ERROR! | K22: =+I22/J22-1 -> #ERROR!
A23: Gastos Comercializacion | B23: =+'REAL-BDGT2026'!V157 -> 1458982437 | C23: =+'REAL-BDGT2026'!#REF! -> #ERROR! | D23: =+B23/C23-1 -> #ERROR! | F23: =(+D23-$E$6) -> #ERROR! | H23: Gastos Comercializacion | I23: =+C23 -> #ERROR! | J23: =+'REAL-BDGT2026'!#REF! -> #ERROR! | K23: =+I23/J23-1 -> #ERROR!
A24: Riesgo Técnico | B24: =+'REAL-BDGT2026'!V166 -> 0 | C24: =+'REAL-BDGT2026'!#REF! -> #ERROR! | H24: Riesgo Técnico | I24: =+C24 -> #ERROR! | J24: =+'REAL-BDGT2026'!#REF! -> #ERROR!
A25: Total Costos | B25: =SUM(B11:B24) -> 3012760313 | C25: =SUM(C11:C24) -> #ERROR! | D25: =+B25/C25-1 -> #ERROR! | F25: =(+D25-$E$6) -> #ERROR! | H25: Total Costos | I25: =SUM(I11:I24) -> #ERROR! | J25: =SUM(J11:J24) -> #ERROR! | K25: =+I25/J25-1 -> #ERROR!
A28: Premisas Presupuesto 2026
A30: Variables Económicas:
A31: Se asume una inflación del 1,5% mensual | E31: Inflación Anual 19,56%
A32: Se inicia con un dolar BNA enero 1500 y se ajusta el 1,5% mensual | E32: dolar BNA ene-26 | G32: =+dolarbnaene -> 1415 | H32: dolar BNA dic-26 | I32: =+usddic -> 1537.6624
A33: El dolar Mep es el 2,5% por sobre el BNA | E33: dalor Mep ene-26 | G33: =+dolarmepene -> 1460.32 | H33: dolar Mep dic-26 | I33: =+'REAL-BDGT2026'!T200 -> 0
A35: RRHH:
A36: Se consideran 3 ingresos de recursos: 1 desarrollador (enero) + 1 operador (febrero) + 1 desarrollador (abril)
A37: se considera incremento salarial por performance en Enero del 6,5%
A38: se considera incremento salarial por ipc acumulado trimestral en Abril, Julio y Octubre
A40: Recambio Tecnológico:
A41: Se considera compra de notebook y monitor unicamente en los 3 casos de nuevos recursos
A42: Se considera recambio de celular 1 por mes
A44: Proveedores:
A45: Se prevee una reducción de la contratación del proveedor Reserv al 50% en todas sus lineas desde el mes de Julio2026

Sheet P&L2026
B1: REAL | C1: REAL | D1: REAL | E1: REAL | F1: REAL | G1: REAL | H1: REAL | I1: REAL | J1: REAL | K1: REAL | L1: REAL | M1: REAL | O1: REAL ACUM MAR | R1: BDGT | S1: BDGT | T1: BDGT | U1: BDGT | V1: BDGT | W1: BDGT | X1: BDGT | Y1: BDGT | Z1: BDGT | AA1: BDGT | AB1: BDGT | AC1: BDGT | AE1: BDGT ACUM MAR
A2: P&L | B2: 46023 | C2: 46055 | D2: 46084 | E2: 46116 | F2: 46147 | G2: 46179 | H2: 46210 | I2: 46242 | J2: =+I2+31 -> 46273 | K2: =+J2+31 -> 46304 | L2: =+K2+31 -> 46335 | M2: =+L2+31 -> 46366 | O2: 2026 | R2: 46023 | S2: 46055 | T2: 46084 | U2: 46116 | V2: 46147 | W2: 46179 | X2: 46210 | Y2: 46242 | Z2: 46273 | AA2: 46304 | AB2: 46335 | AC2: 46366 | AE2: 2026
A3: Revenue | B3: ='REAL-BDGT2026'!I40 -> 2033358817 | C3: ='REAL-BDGT2026'!J40 -> 1982638579 | D3: ='REAL-BDGT2026'!K40 -> 2145968560 | E3: ='REAL-BDGT2026'!L40 -> 2238128327 | F3: ='REAL-BDGT2026'!M40 -> 0 | G3: ='REAL-BDGT2026'!N40 -> 0 | H3: ='REAL-BDGT2026'!O40 -> 0 | I3: ='REAL-BDGT2026'!P40 -> 0 | ... M3: ='REAL-BDGT2026'!T40 -> 0 | O3: =SUM(B3:D3) -> 6161965956 | R3: 1.9576561e+09 | S3: 1.8321659e+09 | T3: 1.9897946e+09 | U3: 2.0930368e+09 | V3: 2.2123595e+09 | W3: 2.2232164e+09 | X3: 2.4567705e+09 | Y3: 2.4265489e+09 | Z3: 2.5494244e+09 | AA3: 2.6712355e+09 | AB3: 2.613006e+09 | AC3: 2.6970105e+09 | AE3: =SUM(R3:T3) -> 5779616651
A4: Sales Tax | B4: ='REAL-BDGT2026'!I41 -> -1.2061955e+08 | C4: ='REAL-BDGT2026'!J41 -> -124410617 | D4: ='REAL-BDGT2026'!K41 -> -1.2598475e+08 | E4: ='REAL-BDGT2026'!L41 -> -1.1082338e+08 | F4: ='REAL-BDGT2026'!M41 -> 0 | G4: ='REAL-BDGT2026'!N41 -> 0 | H4: ='REAL-BDGT2026'!O41 -> 0 | I4: ='REAL-BDGT2026'!P41 -> 0 | ... M4: ='REAL-BDGT2026'!T41 -> 0 | O4: =SUM(B4:D4) -> -371014912 | R4: -97882807 | S4: -91608295 | T4: -99489730 | U4: -1.0465184e+08 | V4: -1.1061798e+08 | W4: -1.1116082e+08 | X4: -1.2283853e+08 | Y4: -1.2132744e+08 | Z4: -1.2747122e+08 | AA4: -1.3356178e+08 | AB4: -1.306503e+08 | AC4: -1.3485052e+08 | AE4: =SUM(R4:T4) -> -2.8898083e+08
A5: Cost of sales | B5: =-SUMIF('REAL-BDGT2026'!$G$43:$G$191,$A5,'REAL-BDGT2026'!I$43:I$191) -> -5.3565596e+08 | C5: =-SUMIF('REAL-BDGT2026'!$G$43:$G$191,$A5,'REAL-BDGT2026'!J$43:J$191) -> -5.1628252e+08 | D5: =-SUMIF('REAL-BDGT2026'!$G$43:$G$191,$A5,'REAL-BDGT2026'!K$43:K$191) -> -5.5469661e+08 | E5: =-SUMIF('REAL-BDGT2026'!$G$43:$G$191,$A5,'REAL-BDGT2026'!L$43:L$191) -> -5.3011378e+08 | F5: =-SUMIF('REAL-BDGT2026'!$G$43:$G$191,$A5,'REAL-BDGT2026'!M$43:M$191) -> 0 | G5: =-SUMIF('REAL-BDGT2026'!$G$43:$G$191,$A5,'REAL-BDGT2026'!N$43:N$191) -> 0 | H5: =-SUMIF('REAL-BDGT2026'!$G$43:$G$191,$A5,'REAL-BDGT2026'!O$43:O$191) -> 0 | I5: =-SUMIF('REAL-BDGT2026'!$G$43:$G$191,$A5,'REAL-BDGT2026'!P$43:P$191) -> 0 | ... M5: =-SUMIF('REAL-BDGT2026'!$G$43:$G$191,$A5,'REAL-BDGT2026'!T$43:T$191) -> 0 | O5: =SUM(B5:D5) -> -1606635081 | R5: -5.9572984e+08 | S5: -5.5437848e+08 | T5: -5.8393416e+08 | U5: -6.2675362e+08 | V5: -6.513464e+08 | W5: -6.6555387e+08 | X5: -9.6075565e+08 | Y5: -7.3262158e+08 | Z5: -7.7317055e+08 | AA5: -8.2446615e+08 | AB5: -8.2072176e+08 | AC5: -8.5269618e+08 | AE5: =SUM(R5:T5) -> -1734042476
A6: Gross margin | B6: =SUM(B3:B5) -> 1377083313 | C6: =SUM(C3:C5) -> 1341945446 | D6: =SUM(D3:D5) -> 1465287204 | E6: =SUM(E3:E5) -> 1597191163 | F6: =SUM(F3:F5) -> 0 | G6: =SUM(G3:G5) -> 0 | H6: =SUM(H3:H5) -> 0 | I6: =SUM(I3:I5) -> 0 | ... M6: =SUM(M3:M5) -> 0 | O6: =SUM(B6:D6) -> 4184315963 | R6: 1.2640435e+09 | S6: 1.1861791e+09 | T6: 1.3063707e+09 | U6: 1.3616313e+09 | V6: 1.4503952e+09 | W6: 1.4465017e+09 | X6: 1.3731763e+09 | Y6: 1.5725998e+09 | Z6: 1.6487826e+09 | AA6: 1.7132076e+09 | AB6: 1.6616339e+09 | AC6: 1.7094638e+09 | AE6: =SUM(R6:T6) -> 3756593343
A7: % | B7: =B6/B3 -> 0.6772456 | C7: =C6/C3 -> 0.67684825 | D7: =D6/D3 -> 0.68280926 | E7: =E6/E3 -> 0.71362805 | F7: =F6/F3 -> #DIV/0! | G7: =G6/G3 -> #DIV/0! | H7: =H6/H3 -> #DIV/0! | I7: =I6/I3 -> #DIV/0! | ... M7: =M6/M3 -> #DIV/0! | O7: =O6/O3 -> 0.67905535 | R7: =R6/R3 -> 0.6456923 | S7: =S6/S3 -> 0.64741906 | T7: 0.65653546 | U7: 0.65055298 | V7: 0.65558745 | W7: 0.65063469 | X7: 0.55893553 | Y7: 0.64808085 | Z7: 0.64672741 | AA7: 0.641354 | AB7: 0.63590896 | AC7: 0.63383654 | AE7: =AE6/AE3 -> 0.64997275
A8: Salaries&Social Security | B8: =-SUMIF('REAL-BDGT2026'!$G$43:$G$191,$A8,'REAL-BDGT2026'!I$43:I$191) -> -1.4832938e+08 | C8: =-SUMIF('REAL-BDGT2026'!$G$43:$G$191,$A8,'REAL-BDGT2026'!J$43:J$191) -> -1.4584772e+08 | D8: =-SUMIF('REAL-BDGT2026'!$G$43:$G$191,$A8,'REAL-BDGT2026'!K$43:K$191) -> -3.1817162e+08 | E8: =-SUMIF('REAL-BDGT2026'!$G$43:$G$191,$A8,'REAL-BDGT2026'!L$43:L$191) -> -1.4927063e+08 | F8: =-SUMIF('REAL-BDGT2026'!$G$43:$G$191,$A8,'REAL-BDGT2026'!M$43:M$191) -> 0 | G8: =-SUMIF('REAL-BDGT2026'!$G$43:$G$191,$A8,'REAL-BDGT2026'!N$43:N$191) -> 0 | H8: =-SUMIF('REAL-BDGT2026'!$G$43:$G$191,$A8,'REAL-BDGT2026'!O$43:O$191) -> 0 | I8: =-SUMIF('REAL-BDGT2026'!$G$43:$G$191,$A8,'REAL-BDGT2026'!P$43:P$191) -> 0 | ... M8: =-SUMIF('REAL-BDGT2026'!$G$43:$G$191,$A8,'REAL-BDGT2026'!T$43:T$191) -> 0 | O8: =SUM(B8:D8) -> -6.1234873e+08 | R8: -1.7592659e+08 | S8: -1.8009192e+08 | T8: -1.8025972e+08 | U8: -1.9209483e+08 | V8: -1.9162161e+08 | W8: -1.9179708e+08 | X8: -1.9995305e+08 | Y8: -2.0013382e+08 | Z8: -2.0031731e+08 | AA8: -2.0783924e+08 | AB8: -2.0802828e+08 | AC8: -2.0822014e+08 | AE8: =SUM(R8:T8) -> -5.3627823e+08
A9: Office&office related | B9: =-SUMIF('REAL-BDGT2026'!$G$43:$G$191,$A9,'REAL-BDGT2026'!I$43:I$191) -> -9170663.2 | C9: =-SUMIF('REAL-BDGT2026'!$G$43:$G$191,$A9,'REAL-BDGT2026'!J$43:J$191) -> -10435567 | D9: =-SUMIF('REAL-BDGT2026'!$G$43:$G$191,$A9,'REAL-BDGT2026'!K$43:K$191) -> -9906459 | E9: =-SUMIF('REAL-BDGT2026'!$G$43:$G$191,$A9,'REAL-BDGT2026'!L$43:L$191) -> -10670610 | F9: =-SUMIF('REAL-BDGT2026'!$G$43:$G$191,$A9,'REAL-BDGT2026'!M$43:M$191) -> 0 | G9: =-SUMIF('REAL-BDGT2026'!$G$43:$G$191,$A9,'REAL-BDGT2026'!N$43:N$191) -> 0 | H9: =-SUMIF('REAL-BDGT2026'!$G$43:$G$191,$A9,'REAL-BDGT2026'!O$43:O$191) -> 0 | I9: =-SUMIF('REAL-BDGT2026'!$G$43:$G$191,$A9,'REAL-BDGT2026'!P$43:P$191) -> 0 | ... M9: =-SUMIF('REAL-BDGT2026'!$G$43:$G$191,$A9,'REAL-BDGT2026'!T$43:T$191) -> 0 | O9: =SUM(B9:D9) -> -29512689 | R9: -12582076 | S9: -12400446 | T9: -10625450 | U9: -12794270 | V9: -14325916 | W9: -11309375 | X9: -13960929 | Y9: -11671445 | Z9: -11845703 | AA9: -13045412 | AB9: -12225298 | AC9: -18388450 | AE9: =SUM(R9:T9) -> -35607972
A10: Professional fees | B10: =-SUMIF('REAL-BDGT2026'!$G$43:$G$169,$A10,'REAL-BDGT2026'!I$43:I$169) -> -39780586 | C10: =-SUMIF('REAL-BDGT2026'!$G$43:$G$169,$A10,'REAL-BDGT2026'!J$43:J$169) -> -38581588 | D10: =-SUMIF('REAL-BDGT2026'!$G$43:$G$169,$A10,'REAL-BDGT2026'!K$43:K$169) -> -44021552 | E10: =-SUMIF('REAL-BDGT2026'!$G$43:$G$169,$A10,'REAL-BDGT2026'!L$43:L$169) -> -51875614 | F10: =-SUMIF('REAL-BDGT2026'!$G$43:$G$169,$A10,'REAL-BDGT2026'!M$43:M$169) -> 0 | G10: =-SUMIF('REAL-BDGT2026'!$G$43:$G$169,$A10,'REAL-BDGT2026'!N$43:N$169) -> 0 | H10: =-SUMIF('REAL-BDGT2026'!$G$43:$G$169,$A10,'REAL-BDGT2026'!O$43:O$169) -> 0 | I10: =-SUMIF('REAL-BDGT2026'!$G$43:$G$169,$A10,'REAL-BDGT2026'!P$43:P$169) -> 0 | ... M10: =-SUMIF('REAL-BDGT2026'!$G$43:$G$169,$A10,'REAL-BDGT2026'!T$43:T$169) -> 0 | O10: =SUM(B10:D10) -> -1.2238372e+08 | R10: -45017725 | S10: -43827791 | T10: -40064810 | U10: -46990029 | V10: -41715304 | W10: -41724856 | X10: -30523302 | Y10: -33841431 | Z10: -30882057 | AA10: -31917557 | AB10: -31699169 | AC10: -31709614 | AE10: =SUM(R10:T10) -> -1.2891033e+08
A11: Travel | B11: =-SUMIF('REAL-BDGT2026'!$G$43:$G$169,$A11,'REAL-BDGT2026'!I$43:I$140) -> 0 | C11: =-SUMIF('REAL-BDGT2026'!$G$43:$G$169,$A11,'REAL-BDGT2026'!J$43:J$140) -> 0 | D11: =-SUMIF('REAL-BDGT2026'!$G$43:$G$191,$A11,'REAL-BDGT2026'!K$43:K$191) -> 0 | E11: =-SUMIF('REAL-BDGT2026'!$G$43:$G$191,$A11,'REAL-BDGT2026'!L$43:L$191) -> 0 | F11: =-SUMIF('REAL-BDGT2026'!$G$43:$G$191,$A11,'REAL-BDGT2026'!M$43:M$191) -> 0 | G11: =-SUMIF('REAL-BDGT2026'!$G$43:$G$191,$A11,'REAL-BDGT2026'!N$43:N$191) -> 0 | H11: =-SUMIF('REAL-BDGT2026'!$G$43:$G$191,$A11,'REAL-BDGT2026'!O$43:O$191) -> 0 | I11: =-SUMIF('REAL-BDGT2026'!$G$43:$G$191,$A11,'REAL-BDGT2026'!P$43:P$191) -> 0 | J11: =-SUMIF('REAL-BDGT2026'!$G$43:$G$191,$A11,'REAL-BDGT2026'!Q$43:Q$191) -> 0 | K11: =-SUMIF('REAL-BDGT2026'!$G$43:$G$191,$A11,'REAL-BDGT2026'!R$43:R$191) -> 0 | ... M11: =-SUMIF('REAL-BDGT2026'!$G$43:$G$191,$A11,'REAL-BDGT2026'!T$43:T$191) -> 0 | O11: =SUM(B11:D11) -> 0 | R11: 0 | S11: 0 | T11: 0 | U11: 0 | V11: 0 | W11: 0 | X11: 0 | Y11: 0 | Z11: 0 | AA11: 0 | AB11: 0 | AC11: 0 | AE11: =SUM(R11:T11) -> 0
A12: Marketing&Advertising | B12: =-SUMIF('REAL-BDGT2026'!$G$43:$G$169,$A12,'REAL-BDGT2026'!I$43:I$140) -> 0 | C12: =-SUMIF('REAL-BDGT2026'!$G$43:$G$169,$A12,'REAL-BDGT2026'!J$43:J$140) -> 0 | D12: =-SUMIF('REAL-BDGT2026'!$G$43:$G$191,$A12,'REAL-BDGT2026'!K$43:K$191) -> 0 | E12: =-SUMIF('REAL-BDGT2026'!$G$43:$G$191,$A12,'REAL-BDGT2026'!L$43:L$191) -> 0 | F12: =-SUMIF('REAL-BDGT2026'!$G$43:$G$191,$A12,'REAL-BDGT2026'!M$43:M$191) -> 0 | G12: =-SUMIF('REAL-BDGT2026'!$G$43:$G$191,$A12,'REAL-BDGT2026'!N$43:N$191) -> 0 | H12: =-SUMIF('REAL-BDGT2026'!$G$43:$G$191,$A12,'REAL-BDGT2026'!O$43:O$191) -> 0 | I12: =-SUMIF('REAL-BDGT2026'!$G$43:$G$191,$A12,'REAL-BDGT2026'!P$43:P$191) -> 0 | J12: =-SUMIF('REAL-BDGT2026'!$G$43:$G$191,$A12,'REAL-BDGT2026'!Q$43:Q$191) -> 0 | K12: =-SUMIF('REAL-BDGT2026'!$G$43:$G$191,$A12,'REAL-BDGT2026'!R$43:R$191) -> 0 | ... M12: =-SUMIF('REAL-BDGT2026'!$G$43:$G$191,$A12,'REAL-BDGT2026'!T$43:T$191) -> 0 | O12: =SUM(B12:D12) -> 0 | R12: 0 | S12: 0 | T12: 0 | U12: 0 | V12: 0 | W12: 0 | X12: 0 | Y12: 0 | Z12: 0 | AA12: 0 | AB12: 0 | AC12: 0 | AE12: =SUM(R12:T12) -> 0
A13: Other taxes | B13: =-SUMIF('REAL-BDGT2026'!$G$43:$G$191,$A13,'REAL-BDGT2026'!I$43:I$191) -> -15332426 | C13: =-SUMIF('REAL-BDGT2026'!$G$43:$G$191,$A13,'REAL-BDGT2026'!J$43:J$191) -> -12269412 | D13: =-SUMIF('REAL-BDGT2026'!$G$43:$G$191,$A13,'REAL-BDGT2026'!K$43:K$191) -> -6631113 | E13: =-SUMIF('REAL-BDGT2026'!$G$43:$G$191,$A13,'REAL-BDGT2026'!L$43:L$191) -> -2361718.3 | F13: =-SUMIF('REAL-BDGT2026'!$G$43:$G$191,$A13,'REAL-BDGT2026'!M$43:M$191) -> 0 | G13: =-SUMIF('REAL-BDGT2026'!$G$43:$G$191,$A13,'REAL-BDGT2026'!N$43:N$191) -> 0 | H13: =-SUMIF('REAL-BDGT2026'!$G$43:$G$191,$A13,'REAL-BDGT2026'!O$43:O$191) -> 0 | I13: =-SUMIF('REAL-BDGT2026'!$G$43:$G$191,$A13,'REAL-BDGT2026'!P$43:P$191) -> 0 | ... M13: =-SUMIF('REAL-BDGT2026'!$G$43:$G$191,$A13,'REAL-BDGT2026'!T$43:T$191) -> 0 | O13: =SUM(B13:D13) -> -34232951 | R13: -2537.5 | S13: -2575.5625 | T13: -2614.1959 | U13: -2653.4089 | V13: -15008709 | W13: -15115280 | X13: -17647020 | Y13: -16414920 | Z13: -17185561 | AA13: -18061815 | AB13: -17760834 | AC13: -18347103 | AE13: =SUM(R13:T13) -> -7727.2584
A14: Miscellaneous | B14: =-SUMIF('REAL-BDGT2026'!$G$43:$G$169,$A14,'REAL-BDGT2026'!I$43:I$140) -> 0 | C14: =-SUMIF('REAL-BDGT2026'!$G$43:$G$169,$A14,'REAL-BDGT2026'!J$43:J$140) -> 0 | D14: =-SUMIF('REAL-BDGT2026'!$G$43:$G$191,$A14,'REAL-BDGT2026'!K$43:K$191) -> 0 | E14: =-SUMIF('REAL-BDGT2026'!$G$43:$G$191,$A14,'REAL-BDGT2026'!L$43:L$191) -> 0 | F14: =-SUMIF('REAL-BDGT2026'!$G$43:$G$191,$A14,'REAL-BDGT2026'!M$43:M$191) -> 0 | G14: =-SUMIF('REAL-BDGT2026'!$G$43:$G$191,$A14,'REAL-BDGT2026'!N$43:N$191) -> 0 | H14: =-SUMIF('REAL-BDGT2026'!$G$43:$G$191,$A14,'REAL-BDGT2026'!O$43:O$191) -> 0 | I14: =-SUMIF('REAL-BDGT2026'!$G$43:$G$191,$A14,'REAL-BDGT2026'!P$43:P$191) -> 0 | J14: =-SUMIF('REAL-BDGT2026'!$G$43:$G$191,$A14,'REAL-BDGT2026'!Q$43:Q$191) -> 0 | K14: =-SUMIF('REAL-BDGT2026'!$G$43:$G$191,$A14,'REAL-BDGT2026'!R$43:R$191) -> 0 | ... M14: =-SUMIF('REAL-BDGT2026'!$G$43:$G$191,$A14,'REAL-BDGT2026'!T$43:T$191) -> 0 | O14: =SUM(B14:D14) -> 0 | R14: 0 | S14: 0 | T14: 0 | U14: 0 | V14: 0 | W14: 0 | X14: 0 | Y14: 0 | Z14: 0 | AA14: 0 | AB14: 0 | AC14: 0 | AE14: =SUM(R14:T14) -> 0
A15: EBITDA | B15: =SUM(B6:B14) -> 1164470259 | C15: =SUM(C6:C14) -> 1134811155 | D15: =SUM(D6:D14) -> 1086556458 | E15: =SUM(E6:E14) -> 1383012588 | F15: =SUM(F6:F14) -> #DIV/0! | G15: =SUM(G6:G14) -> #DIV/0! | H15: =SUM(H6:H14) -> #DIV/0! | I15: =SUM(I6:I14) -> #DIV/0! | ... M15: =SUM(M6:M14) -> #DIV/0! | O15: =SUM(B15:D15) -> 3385837873 | R15: 1.0305146e+09 | S15: 9.498564e+08 | T15: 1.0754181e+09 | U15: 1.1097495e+09 | V15: 1.1877236e+09 | W15: 1.1865551e+09 | X15: 1.111092e+09 | Y15: 1.3105382e+09 | Z15: 1.388552e+09 | AA15: 1.4423436e+09 | AB15: 1.3919203e+09 | AC15: 1.4327985e+09 | AE15: =SUM(R15:T15) -> 3055789090
A16: % | B16: =B15/B3 -> 0.57268311 | C16: =C15/C3 -> 0.57237419 | D16: =D15/D3 -> 0.5063245 | E16: =E15/E3 -> 0.61793266 | F16: =F15/F3 -> #DIV/0! | G16: =G15/G3 -> #DIV/0! | H16: =H15/H3 -> #DIV/0! | I16: =I15/I3 -> #DIV/0! | ... M16: =M15/M3 -> #DIV/0! | O16: =O15/O3 -> 0.54947364 | R16: =R15/R3 -> 0.52640223 | S16: =S15/S3 -> 0.51843362 | T16: 0.5404669 | U16: 0.53021024 | V16: 0.53685832 | W16: 0.53371103 | X16: 0.45225715 | Y16: 0.54008318 | Z16: 0.54465314 | AA16: 0.53995372 | AB16: 0.5326893 | AC16: 0.53125432 | AE16: =AE15/AE3 -> 0.5287183
A17: Exchange rate differences | B17: =-SUMIF('REAL-BDGT2026'!$G$43:$G$191,$A17,'REAL-BDGT2026'!I$43:I$140) -> -140088 | C17: =-SUMIF('REAL-BDGT2026'!$G$43:$G$191,$A17,'REAL-BDGT2026'!J$43:J$140) -> 4508 | D17: =-SUMIF('REAL-BDGT2026'!$G$43:$G$191,$A17,'REAL-BDGT2026'!K$43:K$191) -> 5728 | E17: =-SUMIF('REAL-BDGT2026'!$G$43:$G$191,$A17,'REAL-BDGT2026'!L$43:L$191) -> -47373.53 | F17: =-SUMIF('REAL-BDGT2026'!$G$43:$G$191,$A17,'REAL-BDGT2026'!M$43:M$191) -> 0 | G17: =-SUMIF('REAL-BDGT2026'!$G$43:$G$191,$A17,'REAL-BDGT2026'!N$43:N$191) -> 0 | H17: =-SUMIF('REAL-BDGT2026'!$G$43:$G$191,$A17,'REAL-BDGT2026'!O$43:O$191) -> 0 | I17: =-SUMIF('REAL-BDGT2026'!$G$43:$G$191,$A17,'REAL-BDGT2026'!P$43:P$191) -> 0 | J17: =-SUMIF('REAL-BDGT2026'!$G$43:$G$191,$A17,'REAL-BDGT2026'!Q$43:Q$191) -> 0 | K17: =-SUMIF('REAL-BDGT2026'!$G$43:$G$191,$A17,'REAL-BDGT2026'!R$43:R$191) -> 0 | ... M17: =-SUMIF('REAL-BDGT2026'!$G$43:$G$191,$A17,'REAL-BDGT2026'!T$43:T$191) -> 0 | O17: =SUM(B17:D17) -> -129852 | R17: 0 | S17: 0 | T17: 0 | U17: 0 | V17: 0 | W17: 0 | X17: 0 | Y17: 0 | Z17: 0 | AA17: 0 | AB17: 0 | AC17: 0 | AE17: =SUM(R17:T17) -> 0
A18: Financing activities | B18: =SUMIF('REAL-BDGT2026'!$G$43:$G$191,$A18,'REAL-BDGT2026'!I$43:I$191)*-1 -> 2.3808781e+08 | C18: =SUMIF('REAL-BDGT2026'!$G$43:$G$191,$A18,'REAL-BDGT2026'!J$43:J$191)*-1 -> 218300896 | D18: =SUMIF('REAL-BDGT2026'!$G$43:$G$191,$A18,'REAL-BDGT2026'!K$43:K$191)*-1 -> 262865752 | E18: =SUMIF('REAL-BDGT2026'!$G$43:$G$191,$A18,'REAL-BDGT2026'!L$43:L$191)*-1 -> 85208676 | F18: =SUMIF('REAL-BDGT2026'!$G$43:$G$191,$A18,'REAL-BDGT2026'!M$43:M$191)*-1 -> 0 | G18: =SUMIF('REAL-BDGT2026'!$G$43:$G$191,$A18,'REAL-BDGT2026'!N$43:N$191)*-1 -> 0 | H18: =SUMIF('REAL-BDGT2026'!$G$43:$G$191,$A18,'REAL-BDGT2026'!O$43:O$191)*-1 -> 0 | I18: =SUMIF('REAL-BDGT2026'!$G$43:$G$191,$A18,'REAL-BDGT2026'!P$43:P$191)*-1 -> 0 | ... M18: =SUMIF('REAL-BDGT2026'!$G$43:$G$191,$A18,'REAL-BDGT2026'!T$43:T$191)*-1 -> 0 | O18: =SUM(B18:D18) -> 7.1925446e+08 | R18: 0 | S18: 0 | T18: 0 | U18: 0 | V18: 0 | W18: 0 | X18: 0 | Y18: 0 | Z18: 0 | AA18: 0 | AB18: 0 | AC18: 0 | AE18: =SUM(R18:T18) -> 0
A19: Interest | B19: =SUMIF('REAL-BDGT2026'!$G$43:$G$191,$A19,'REAL-BDGT2026'!I$43:I$191)*-1 -> 0 | C19: =SUMIF('REAL-BDGT2026'!$G$43:$G$191,$A19,'REAL-BDGT2026'!J$43:J$191)*-1 -> -3024427 | D19: =SUMIF('REAL-BDGT2026'!$G$43:$G$191,$A19,'REAL-BDGT2026'!K$43:K$191) -> 0 | E19: =SUMIF('REAL-BDGT2026'!$G$43:$G$191,$A19,'REAL-BDGT2026'!L$43:L$191)*-1 -> -27050.63 | F19: =SUMIF('REAL-BDGT2026'!$G$43:$G$191,$A19,'REAL-BDGT2026'!M$43:M$191)*-1 -> 0 | G19: =SUMIF('REAL-BDGT2026'!$G$43:$G$191,$A19,'REAL-BDGT2026'!N$43:N$191)*-1 -> 0 | H19: =SUMIF('REAL-BDGT2026'!$G$43:$G$191,$A19,'REAL-BDGT2026'!O$43:O$191)*-1 -> 0 | I19: =SUMIF('REAL-BDGT2026'!$G$43:$G$191,$A19,'REAL-BDGT2026'!P$43:P$191)*-1 -> 0 | J19: =SUMIF('REAL-BDGT2026'!$G$43:$G$191,$A19,'REAL-BDGT2026'!Q$43:Q$191)*-1 -> 0 | K19: =SUMIF('REAL-BDGT2026'!$G$43:$G$191,$A19,'REAL-BDGT2026'!R$43:R$191)*-1 -> 0 | L19: =SUMIF('REAL-BDGT2026'!$G$43:$G$191,$A19,'REAL-BDGT2026'!S$43:S$191)*-1 -> 0 | M19: =SUMIF('REAL-BDGT2026'!$G$43:$G$191,$A19,'REAL-BDGT2026'!T$43:T$191)*-1 -> 0 | O19: =SUM(B19:D19) -> -3024427 | R19: 0 | S19: 0 | T19: 0 | U19: 0 | V19: 0 | W19: 0 | X19: 0 | Y19: 0 | Z19: 0 | AA19: 0 | AB19: 0 | AC19: 0 | AE19: =SUM(R19:T19) -> 0
A20: Other income | B20: =-SUMIF('REAL-BDGT2026'!$G$43:$G$191,$A20,'REAL-BDGT2026'!I$43:I$191) -> -67750 | C20: =-SUMIF('REAL-BDGT2026'!$G$43:$G$191,$A20,'REAL-BDGT2026'!J$43:J$191) -> -49000 | D20: =-SUMIF('REAL-BDGT2026'!$G$43:$G$191,$A20,'REAL-BDGT2026'!K$43:K$191) -> -49000 | E20: =-SUMIF('REAL-BDGT2026'!$G$43:$G$191,$A20,'REAL-BDGT2026'!L$43:L$191) -> -49000 | F20: =-SUMIF('REAL-BDGT2026'!$G$43:$G$191,$A20,'REAL-BDGT2026'!M$43:M$191) -> 0 | G20: =-SUMIF('REAL-BDGT2026'!$G$43:$G$191,$A20,'REAL-BDGT2026'!N$43:N$191) -> 0 | H20: =-SUMIF('REAL-BDGT2026'!$G$43:$G$191,$A20,'REAL-BDGT2026'!O$43:O$191) -> 0 | I20: =-SUMIF('REAL-BDGT2026'!$G$43:$G$191,$A20,'REAL-BDGT2026'!P$43:P$191) -> 0 | ... M20: =-SUMIF('REAL-BDGT2026'!$G$43:$G$191,$A20,'REAL-BDGT2026'!T$43:T$191) -> 0 | O20: =SUM(B20:D20) -> -165750 | R20: -70000 | S20: -70000 | T20: -70000 | U20: -70000 | V20: -70000 | W20: -70000 | X20: -70000 | Y20: -70000 | Z20: -70000 | AA20: -70000 | AB20: -70000 | AC20: -70000 | AE20: =SUM(R20:T20) -> -210000
A21: Depreciation | B21: =-SUMIF('REAL-BDGT2026'!$G$43:$G$191,$A21,'REAL-BDGT2026'!I$43:I$191) -> -20874038 | C21: =-SUMIF('REAL-BDGT2026'!$G$43:$G$191,$A21,'REAL-BDGT2026'!J$43:J$191) -> -20874038 | D21: =-SUMIF('REAL-BDGT2026'!$G$43:$G$191,$A21,'REAL-BDGT2026'!K$43:K$191) -> -21322923 | E21: =-SUMIF('REAL-BDGT2026'!$G$43:$G$191,$A21,'REAL-BDGT2026'!L$43:L$191) -> -21082522 | F21: =-SUMIF('REAL-BDGT2026'!$G$43:$G$191,$A21,'REAL-BDGT2026'!M$43:M$191) -> 0 | G21: =-SUMIF('REAL-BDGT2026'!$G$43:$G$191,$A21,'REAL-BDGT2026'!N$43:N$191) -> 0 | H21: =-SUMIF('REAL-BDGT2026'!$G$43:$G$191,$A21,'REAL-BDGT2026'!O$43:O$191) -> 0 | I21: =-SUMIF('REAL-BDGT2026'!$G$43:$G$191,$A21,'REAL-BDGT2026'!P$43:P$191) -> 0 | ... M21: =-SUMIF('REAL-BDGT2026'!$G$43:$G$191,$A21,'REAL-BDGT2026'!T$43:T$191) -> 0 | O21: =SUM(B21:D21) -> -63070999 | R21: -20362316 | S21: -20362316 | T21: -20362316 | U21: -20362316 | V21: -20362316 | W21: -20362316 | X21: -20362316 | Y21: -20362316 | Z21: -20362316 | AA21: -20362316 | AB21: -20362316 | AC21: -20362316 | AE21: =SUM(R21:T21) -> -61086948
A22: Income tax | B22: =-SUMIF('REAL-BDGT2026'!$G$43:$G$191,$A22,'REAL-BDGT2026'!I$43:I$191) -> -4.8831943e+08 | C22: =-SUMIF('REAL-BDGT2026'!$G$43:$G$191,$A22,'REAL-BDGT2026'!J$43:J$191) -> -4.6233286e+08 | D22: =-SUMIF('REAL-BDGT2026'!$G$43:$G$191,$A22,'REAL-BDGT2026'!K$43:K$191) -> -4.7773254e+08 | E22: =-SUMIF('REAL-BDGT2026'!$G$43:$G$191,$A22,'REAL-BDGT2026'!L$43:L$191) -> -5.1250147e+08 | F22: =-SUMIF('REAL-BDGT2026'!$G$43:$G$191,$A22,'REAL-BDGT2026'!M$43:M$191) -> 0 | G22: =-SUMIF('REAL-BDGT2026'!$G$43:$G$191,$A22,'REAL-BDGT2026'!N$43:N$191) -> 0 | H22: =-SUMIF('REAL-BDGT2026'!$G$43:$G$191,$A22,'REAL-BDGT2026'!O$43:O$191) -> 0 | I22: =-SUMIF('REAL-BDGT2026'!$G$43:$G$191,$A22,'REAL-BDGT2026'!P$43:P$191) -> 0 | ... M22: =-SUMIF('REAL-BDGT2026'!$G$43:$G$191,$A22,'REAL-BDGT2026'!T$43:T$191) -> 0 | O22: =SUM(B22:D22) -> -1428384831 | R22: -3.5355329e+08 | S22: -3.2532293e+08 | T22: -3.6926953e+08 | U22: -3.8128553e+08 | V22: -4.0857646e+08 | W22: -4.0816747e+08 | X22: -3.817554e+08 | Y22: -4.5156157e+08 | Z22: -4.7886639e+08 | AA22: -4.9769344e+08 | AB22: -4.8004531e+08 | AC22: -4.9435266e+08 | AE22: =SUM(R22:T22) -> -1048145749
A23: Net (loss) income | B23: =SUM(B15:B22) -> 893156763 | C23: =SUM(C15:C22) -> 8.6683623e+08 | D23: =SUM(D15:D22) -> 8.5032348e+08 | E23: =SUM(E15:E22) -> 9.3451384e+08 | F23: =SUM(F15:F22) -> #DIV/0! | G23: =SUM(G15:G22) -> #DIV/0! | H23: =SUM(H15:H22) -> #DIV/0! | I23: =SUM(I15:I22) -> #DIV/0! | ... M23: =SUM(M15:M22) -> #DIV/0! | O23: =SUM(B23:D23) -> 2610316472 | R23: 6.5652896e+08 | S23: 6.0410116e+08 | T23: 6.8571628e+08 | U23: 7.080317e+08 | V23: 7.5871485e+08 | W23: 7.5795531e+08 | X23: 7.0890432e+08 | Y23: 8.3854434e+08 | Z23: 8.892533e+08 | AA23: 9.2421781e+08 | AB23: 8.9144271e+08 | AC23: 9.1801351e+08 | AE23: =SUM(R23:T23) -> 1946346395
A24: % | B24: =B23/(SUM(B3:B4)) -> 0.46695165 | C24: =C23/(SUM(C3:C4)) -> 0.46648541 | D24: =D23/(SUM(D3:D4)) -> 0.42095559 | E24: =E23/(SUM(E3:E4)) -> 0.43929473 | F24: =F23/(SUM(F3:F4)) -> #DIV/0! | G24: =G23/(SUM(G3:G4)) -> #DIV/0! | H24: =H23/(SUM(H3:H4)) -> #DIV/0! | I24: =I23/(SUM(I3:I4)) -> #DIV/0! | ... M24: =M23/(SUM(M3:M4)) -> #DIV/0! | O24: =O23/(SUM(O3:O4)) -> 0.45075782 | R24: =R23/(SUM(R3:R4)) -> 0.35301558 | S24: =S23/(SUM(S3:S4)) -> 0.34707335 | T24: 0.36275433 | U24: 0.35608382 | V24: 0.36099341 | W24: 0.35887091 | X24: 0.30373821 | Y24: 0.3637587 | Z24: 0.3671637 | AA24: 0.36419883 | AB24: 0.3591116 | AC24: 0.35829672 | AE24: =AE23/(SUM(AE3:AE4)) -> 0.3544847

Sheet Cuentas
A2: 5111 | B2: Ingresos por Venta de Servicios
A3: 5121 | B3: Diferencia de Cambio
A4: 5122 | B4: Resultados Financieros -
A5: 5123 | B5: Resultados por tenencia
A6: 5125 | B6: Resultados por tenencia FCI
A7: 5126 | B7: Intereses ganados préstamos accionistas
A8: 5211 | B8: Servicios Profesionales
A9: 5212 | B9: Servicios Call Center
A10: 5213 | B10: Mantenimiento y Soporte Plataforma
A11: 5214 | B11: Evolucion Desarrollo
A12: 5215 | B12: Mantenimiento de Licencias
A13: 5216 | B13: Servicios de CRM de llamadas telefonicas
... A44: 5711 | B44: Intereses Perdidos y Multas

Sheet RRHH-IngresVacyBonos
B1: Ingresos de Personal | H1: ipc estimado
G2: 1 | H2: 1
B3: Meses en los que se suma | G3: =+G2*H3 -> 1.023 | H3: 1.023 | I3: 45955
B4: 2 | C4: desarrolladores | D4: enero y abril | G4: =+G3*H4 -> 1.04346 | H4: 1.02 | I4: 45986
B5: 1 | C5: operaciones | D5: febrero | G5: =+G4*H5 -> 1.0643292 | H5: 1.02 | I5: dic-25
B7: ACTUALIZAR CANTIDAD DE LICENCIAS SEGUN INGRESOS
B10: Calculo Mensual de Vacaciones y Bono | J10: Monto Anual | K10: Prorrateo
G11: a definir por IA | K11: Mensual
F12: ajuste aplicado en cada mes | G12: =+G5 -> 1.0643292 | H12: =+'REAL-BDGT2026'!L196 -> 1.0948416 | I12: =+'REAL-BDGT2026'!O196 -> 1.0863709 | J12: =+'REAL-BDGT2026'!R196 -> 1.0895474
C13: Fuente: Mail Analia de Martin 20/11/2025 | G13: Ene-26 | H13: Abr-25 | I13: 46228 | J13: 46320
C15: Prov. Vacaciones | E15: base salarial dic2025 | F15: 47922601 | G15: =+F15*$G$12 -> 51005423 | H15: =+G15*$H$12 -> 55842859 | I15: =+H15*$I$12 -> 60666055 | J15: =+I15*$J$12 -> 66098542
C16: Prov. Vacaciones (Cargas sociales) | F16: 11501424 | G16: =+F16*$G$12 -> 12241302 | H16: =+G16*$H$12 -> 13402286 | I16: =+H16*$I$12 -> 14559853 | J16: =+I16*$J$12 -> 15863650
C17: Total Provi Vacaciones y Cs Sociales | F17: =SUM(F15:F16) -> 59424025 | G17: =SUM(G15:G16) -> 63246725 | H17: =SUM(H15:H16) -> 69245145 | I17: =SUM(I15:I16) -> 75225908 | J17: =SUM(J15:J16) -> 81962192 | K17: =+J17/12 -> 6830182.6 | L17: =+C15 -> Prov. Vacaciones
C19: Prov. Bono 75% | E19: base salarial dic2025 | F19: 1.3202459e+08 | G19: =+F19*$G$12 -> 1.4051763e+08 | H19: =+G19*$H$12 -> 1.5384454e+08 | I19: =+H19*$I$12 -> 1.6713223e+08 | J19: =+I19*$J$12 -> 1.8209848e+08
C20: Prov. Bono (Cargas sociales) | F20: 31685902 | G20: =+F20*$G$12 -> 33724230 | H20: =+G20*$H$12 -> 36922690 | I20: =+H20*$I$12 -> 40111735 | J20: =+I20*$J$12 -> 43703636
C21: Total Provi Bono y Cs Sociales | F21: =SUM(F19:F20) -> 1.6371049e+08 | G21: =SUM(G19:G20) -> 1.7424186e+08 | H21: =SUM(H19:H20) -> 190767232 | I21: =SUM(I19:I20) -> 207243963 | J21: =SUM(J19:J20) -> 2.2580212e+08 | K21: =+J21/12 -> 18816843 | L21: =+C19 -> Prov. Bono 75%
C23: multiplicador costo total empresa por sueldo bruto | F23: 1.26

Sheet Flk
A2: Dias hábiles 2025 | C2: 20 | D2: 18 | E2: 19 | F2: 21 | G2: 20 | H2: 22 | I2: 20 | J2: 22 | K2: 22 | L2: 19 | M2: 19
B4: REAL | C4: REAL | D4: REAL | E4: REAL | F4: REAL | G4: REAL | H4: REAL | I4: REAL | J4: REAL | K4: RFC | L4: RFC | M4: RFC
A5: REAL TRX 2025 | B5: 45658 | C5: 45689 | D5: 45747 | E5: =+D5+30 -> 45777 | F5: =+E5+30 -> 45807 | G5: =+F5+30 -> 45837 | H5: =+G5+30 -> 45867 | I5: =+H5+30 -> 45897 | J5: =+I5+30 -> 45927 | K5: =+J5+30 -> 45957 | L5: =+K5+30 -> 45987 | M5: =+L5+30 -> 46017
A6: Servicio Basico Online PREPAGAS | B6: 1490306 | C6: 1355716 | D6: 1520755 | E6: 1602317 | F6: 1682330 | G6: 1666122 | H6: 1751014 | I6: 1703302 | J6: 1734745 | K6: 1750000 | L6: 1602317 | M6: 1602317
A7: Servicio Basico Online APROSS | B7: 213669 | C7: 190015 | D7: 208388 | E7: 213716 | F7: 225462 | G7: 230982 | H7: 241030 | I7: 233048 | J7: 233018 | K7: 250000 | L7: 213716 | M7: 213716
A8: Servicio Basico Online IOMA | B8: 763760 | C8: 721443 | D8: 781327 | E8: 818781 | F8: 852102 | G8: 847647 | H8: 914890 | I8: 872560 | J8: 889037 | K8: 910000 | L8: 818781 | M8: 818781
A9: Receta Electrónica Prepagas | B9: 815603 | C9: 797198 | D9: 919640 | E9: 975702 | F9: 1037849 | G9: 1037505 | H9: 1125351 | I9: 1127209 | J9: 1157003 | K9: 1157003 | L9: 975702 | M9: 975702
A10: Receta Electrónica Apross | B10: 213655 | C10: 190000 | D10: 208408 | E10: 213654 | F10: 225525 | G10: 230993 | H10: 241068 | I10: 233115 | J10: 233023 | K10: 233023 | L10: 213654 | M10: 213654
A11: Receta Electrónica IOMA | B11: 220374 | C11: 229948 | D11: 254773 | E11: 260754 | F11: 285776 | G11: 288842 | H11: 324566 | I11: 325357 | J11: 335574 | K11: 335574 | L11: 260754 | M11: 260754
A12: Servicio Basico On Line PAMI | B12: 9286473 | C12: 8514062 | D12: 9117807 | E12: 9173479 | F12: 9361132 | G12: 9051190 | H12: 9745031 | I12: 9274503 | J12: 9473415 | K12: 9600000 | L12: 9173479 | M12: 9173479
A13: Servicio Basico On Line PAMI Imposiciones | B13: 2612360 | C13: 2472690 | D13: 2621948 | E13: 2645479 | F13: 2666197 | G13: 2487094 | H13: 2680119 | I13: 2553801 | J13: 2647447 | K13: 2647447 | L13: 2645479 | M13: 2645479
A14: se prevee un IPC de 1,5% en Julio | C14: =+C25/B25 -> 1.0239831 | D14: =+D25/C25 -> 1.0369941 | E14: =+E25/D25 -> 1.0280128 | F14: =+F25/E25 -> 1.0149833 | G14: =+G25/F25 -> 1.0159859 | H14: =+H25/G25 -> 1.0189716
A16: Variación estacional Prepagas 2025 | B16: =(+B6/#REF!) -> #REF! | C16: =(+#REF!/#REF!) -> #REF! | D16: =(+#REF!/#REF!) -> #REF! | E16: =(+#REF!/#REF!) -> #REF! | F16: =(+#REF!/#REF!) -> #REF! | G16: =(+#REF!/#REF!) -> #REF! | H16: =(+#REF!/#REF!) -> #REF! | I16: =(+#REF!/#REF!) -> #REF! | J16: =(+#REF!/#REF!) -> #REF! | ... M16: =(+#REF!/#REF!) -> #REF!
A17: Variación estacional Apross 2025 | B17: =(+B7/#REF!) -> #REF! | C17: =(+#REF!/#REF!) -> #REF! | D17: =(+#REF!/#REF!) -> #REF! | E17: =(+#REF!/#REF!) -> #REF! | F17: =(+#REF!/#REF!) -> #REF! | G17: =(+#REF!/#REF!) -> #REF! | H17: =(+#REF!/#REF!) -> #REF! | I17: =(+#REF!/#REF!) -> #REF! | J17: =(+#REF!/#REF!) -> #REF! | ... M17: =(+#REF!/#REF!) -> #REF!
A18: Variación estacional IOMA 2025 | B18: =(+B8/#REF!) -> #REF! | C18: =(+#REF!/#REF!) -> #REF! | D18: =(+#REF!/#REF!) -> #REF! | E18: =(+#REF!/#REF!) -> #REF! | F18: =(+#REF!/#REF!) -> #REF! | G18: =(+#REF!/#REF!) -> #REF! | H18: =(+#REF!/#REF!) -> #REF! | I18: =(+#REF!/#REF!) -> #REF! | J18: =(+#REF!/#REF!) -> #REF! | ... M18: =(+#REF!/#REF!) -> #REF!
A19: Variación estacional Rec Elect Prepagas 2025 | B19: =(+B9/#REF!) -> #REF! | H19: =(+#REF!/#REF!) -> #REF! | I19: =(+#REF!/#REF!) -> #REF! | J19: =(+#REF!/#REF!) -> #REF! | K19: =(+#REF!/#REF!) -> #REF! | L19: =(+#REF!/#REF!) -> #REF! | M19: =(+#REF!/#REF!) -> #REF!
A20: Variación estacional Rec Elect Apross 2025 | B20: =(+B10/#REF!) -> #REF! | H20: =(+#REF!/#REF!) -> #REF! | I20: =(+#REF!/#REF!) -> #REF! | J20: =(+#REF!/#REF!) -> #REF! | K20: =(+#REF!/#REF!) -> #REF! | L20: =(+#REF!/#REF!) -> #REF! | M20: =(+#REF!/#REF!) -> #REF!
A21: Variación estacional Rec Elect IOMA 2025 | B21: =(+B11/#REF!) -> #REF! | H21: =(+#REF!/#REF!) -> #REF! | I21: =(+#REF!/#REF!) -> #REF! | J21: =(+#REF!/#REF!) -> #REF! | K21: =(+#REF!/#REF!) -> #REF! | L21: =(+#REF!/#REF!) -> #REF! | M21: =(+#REF!/#REF!) -> #REF!
A24: REAL Precio x TRX 2025 | B24: 45658 | C24: 45689 | D24: 45747 | E24: =+D24+30 -> 45777 | F24: =+E24+30 -> 45807 | G24: =+F24+30 -> 45837 | H24: =+G24+30 -> 45867 | I24: =+H24+30 -> 45897 | J24: =+I24+30 -> 45927 | K24: =+J24+30 -> 45957 | L24: =+K24+30 -> 45987 | M24: =+L24+30 -> 46017
A25: Servicio Basico Online PREPAGAS | B25: 118 | C25: 120.83 | D25: 125.3 | E25: 128.81 | F25: 130.74 | G25: 132.83 | H25: 135.35 | I25: 137.92 | J25: 140.82 | K25: =+J25*(1+$K$34) -> 144.05886 | L25: =+K25*(1+$L$34) -> 146.94004 | M25: =+L25*(1+$M$34) -> 149.87884
A26: Servicio Basico Online APROSS | B26: 118 | C26: 120.83 | D26: 125.3 | E26: 128.81 | F26: 130.74 | G26: 132.83 | H26: 135.35 | I26: 137.92 | J26: 140.82 | K26: =+J26*(1+$K$34) -> 144.05886 | L26: =+K26*(1+$L$34) -> 146.94004 | M26: =+L26*(1+$M$34) -> 149.87884
A27: Servicio Basico Online IOMA | B27: 127.32 | C27: 130.38 | D27: 135.2 | E27: 138.99 | F27: 141.07 | G27: 143.33 | H27: 146.05 | I27: 148.82 | J27: 151.95 | K27: =+J27*(1+$K$34) -> 155.44485 | L27: =+K27*(1+$L$34) -> 158.55375 | M27: =+L27*(1+$M$34) -> 161.72482
A28: Receta Electrónica Prepagas | B28: 9.44 | C28: 9.67 | D28: 10.02 | E28: 10.3 | F28: 10.46 | G28: 10.63 | H28: 10.83 | I28: 11.03 | J28: 11.27 | K28: =+J28*(1+$K$34) -> 11.52921 | L28: =+K28*(1+$L$34) -> 11.759794 | M28: =+L28*(1+$M$34) -> 11.99499
